[Fri May 01 13:44:36.751400 2020] [authz_core:error] [pid 26] [client 172.17.0.1:49198] AH01630: client denied by server configuration: /Mxonline3/Mxonline3/wsgi.py
[Fri May 01 13:44:37.093979 2020] [authz_core:error] [pid 26] [client 172.17.0.1:49198] AH01630: client denied by server configuration: /Mxonline3/Mxonline3/wsgi.py, referer: http://127.0.0.1:89/noindex/css/open-sans.css
[Fri May 01 13:44:37.094072 2020] [authz_core:error] [pid 22] [client 172.17.0.1:49202] AH01630: client denied by server configuration: /Mxonline3/Mxonline3/wsgi.py, referer: http://127.0.0.1:89/noindex/css/open-sans.css
[Fri May 01 13:44:37.106495 2020] [authz_core:error] [pid 22] [client 172.17.0.1:49202] AH01630: client denied by server configuration: /Mxonline3/Mxonline3/wsgi.py, referer: http://127.0.0.1:89/noindex/css/open-sans.css
[Fri May 01 13:44:37.106590 2020] [authz_core:error] [pid 26] [client 172.17.0.1:49198] AH01630: client denied by server configuration: /Mxonline3/Mxonline3/wsgi.py, referer: http://127.0.0.1:89/noindex/css/open-sans.css
[Fri May 01 13:44:37.140949 2020] [authz_core:error] [pid 26] [client 172.17.0.1:49198] AH01630: client denied by server configuration: /Mxonline3/Mxonline3/wsgi.py, referer: http://127.0.0.1:89/
[Fri May 01 13:48:43.497705 2020] [authz_core:error] [pid 24] [client 172.17.0.1:49206] AH01630: client denied by server configuration: /Mxonline3/Mxonline3/wsgi.py
[Fri May 01 13:48:43.727581 2020] [authz_core:error] [pid 24] [client 172.17.0.1:49206] AH01630: client denied by server configuration: /Mxonline3/Mxonline3/wsgi.py, referer: http://127.0.0.1:89/noindex/css/open-sans.css
[Fri May 01 13:48:43.744313 2020] [authz_core:error] [pid 25] [client 172.17.0.1:49210] AH01630: client denied by server configuration: /Mxonline3/Mxonline3/wsgi.py, referer: http://127.0.0.1:89/noindex/css/open-sans.css
[Fri May 01 13:48:43.780465 2020] [authz_core:error] [pid 25] [client 172.17.0.1:49210] AH01630: client denied by server configuration: /Mxonline3/Mxonline3/wsgi.py, referer: http://127.0.0.1:89/noindex/css/open-sans.css
[Fri May 01 13:48:43.795181 2020] [authz_core:error] [pid 25] [client 172.17.0.1:49210] AH01630: client denied by server configuration: /Mxonline3/Mxonline3/wsgi.py, referer: http://127.0.0.1:89/noindex/css/open-sans.css
[Fri May 01 13:48:43.815982 2020] [authz_core:error] [pid 25] [client 172.17.0.1:49210] AH01630: client denied by server configuration: /Mxonline3/Mxonline3/wsgi.py, referer: http://127.0.0.1:89/
[Fri May 01 13:49:55.241205 2020] [authz_core:error] [pid 23] [client 172.17.0.1:49214] AH01630: client denied by server configuration: /Mxonline3/Mxonline3/wsgi.py
[Fri May 01 13:49:55.470843 2020] [authz_core:error] [pid 23] [client 172.17.0.1:49214] AH01630: client denied by server configuration: /Mxonline3/Mxonline3/wsgi.py, referer: http://127.0.0.1:89/noindex/css/open-sans.css
[Fri May 01 13:49:55.470963 2020] [authz_core:error] [pid 44] [client 172.17.0.1:49218] AH01630: client denied by server configuration: /Mxonline3/Mxonline3/wsgi.py, referer: http://127.0.0.1:89/noindex/css/open-sans.css
[Fri May 01 13:49:55.509137 2020] [authz_core:error] [pid 44] [client 172.17.0.1:49218] AH01630: client denied by server configuration: /Mxonline3/Mxonline3/wsgi.py, referer: http://127.0.0.1:89/noindex/css/open-sans.css
[Fri May 01 13:49:55.509137 2020] [authz_core:error] [pid 23] [client 172.17.0.1:49214] AH01630: client denied by server configuration: /Mxonline3/Mxonline3/wsgi.py, referer: http://127.0.0.1:89/noindex/css/open-sans.css
[Fri May 01 13:49:55.533275 2020] [authz_core:error] [pid 23] [client 172.17.0.1:49214] AH01630: client denied by server configuration: /Mxonline3/Mxonline3/wsgi.py, referer: http://127.0.0.1:89/
[Fri May 01 13:49:56.088284 2020] [authz_core:error] [pid 23] [client 172.17.0.1:49214] AH01630: client denied by server configuration: /Mxonline3/Mxonline3/wsgi.py
[Fri May 01 13:49:56.254954 2020] [authz_core:error] [pid 44] [client 172.17.0.1:49218] AH01630: client denied by server configuration: /Mxonline3/Mxonline3/wsgi.py, referer: http://127.0.0.1:89/noindex/css/open-sans.css
[Fri May 01 13:49:56.254953 2020] [authz_core:error] [pid 23] [client 172.17.0.1:49214] AH01630: client denied by server configuration: /Mxonline3/Mxonline3/wsgi.py, referer: http://127.0.0.1:89/noindex/css/open-sans.css
[Fri May 01 13:49:56.286600 2020] [authz_core:error] [pid 23] [client 172.17.0.1:49214] AH01630: client denied by server configuration: /Mxonline3/Mxonline3/wsgi.py, referer: http://127.0.0.1:89/noindex/css/open-sans.css
[Fri May 01 13:49:56.288524 2020] [authz_core:error] [pid 44] [client 172.17.0.1:49218] AH01630: client denied by server configuration: /Mxonline3/Mxonline3/wsgi.py, referer: http://127.0.0.1:89/noindex/css/open-sans.css
[Fri May 01 13:49:56.320787 2020] [authz_core:error] [pid 44] [client 172.17.0.1:49218] AH01630: client denied by server configuration: /Mxonline3/Mxonline3/wsgi.py, referer: http://127.0.0.1:89/
[Fri May 01 13:49:56.391535 2020] [authz_core:error] [pid 44] [client 172.17.0.1:49218] AH01630: client denied by server configuration: /Mxonline3/Mxonline3/wsgi.py
[Fri May 01 13:49:56.519260 2020] [authz_core:error] [pid 44] [client 172.17.0.1:49218] AH01630: client denied by server configuration: /Mxonline3/Mxonline3/wsgi.py, referer: http://127.0.0.1:89/noindex/css/open-sans.css
[Fri May 01 13:49:56.521916 2020] [authz_core:error] [pid 23] [client 172.17.0.1:49214] AH01630: client denied by server configuration: /Mxonline3/Mxonline3/wsgi.py, referer: http://127.0.0.1:89/noindex/css/open-sans.css
[Fri May 01 13:49:56.532419 2020] [authz_core:error] [pid 23] [client 172.17.0.1:49214] AH01630: client denied by server configuration: /Mxonline3/Mxonline3/wsgi.py, referer: http://127.0.0.1:89/noindex/css/open-sans.css
[Fri May 01 13:49:56.533229 2020] [authz_core:error] [pid 44] [client 172.17.0.1:49218] AH01630: client denied by server configuration: /Mxonline3/Mxonline3/wsgi.py, referer: http://127.0.0.1:89/noindex/css/open-sans.css
[Fri May 01 13:49:56.583336 2020] [authz_core:error] [pid 44] [client 172.17.0.1:49218] AH01630: client denied by server configuration: /Mxonline3/Mxonline3/wsgi.py, referer: http://127.0.0.1:89/
[Fri May 01 13:50:17.353657 2020] [authz_core:error] [pid 25] [client 172.17.0.1:49222] AH01630: client denied by server configuration: /Mxonline3/Mxonline3/wsgi.py
[Fri May 01 13:50:17.596607 2020] [authz_core:error] [pid 25] [client 172.17.0.1:49222] AH01630: client denied by server configuration: /Mxonline3/Mxonline3/wsgi.py, referer: http://127.0.0.1:89/
[Fri May 01 13:50:18.582612 2020] [authz_core:error] [pid 25] [client 172.17.0.1:49222] AH01630: client denied by server configuration: /Mxonline3/Mxonline3/wsgi.py
[Fri May 01 13:50:18.749156 2020] [authz_core:error] [pid 25] [client 172.17.0.1:49222] AH01630: client denied by server configuration: /Mxonline3/Mxonline3/wsgi.py, referer: http://127.0.0.1:89/
[Fri May 01 13:50:18.946964 2020] [authz_core:error] [pid 25] [client 172.17.0.1:49222] AH01630: client denied by server configuration: /Mxonline3/Mxonline3/wsgi.py
[Fri May 01 13:50:19.100930 2020] [authz_core:error] [pid 25] [client 172.17.0.1:49222] AH01630: client denied by server configuration: /Mxonline3/Mxonline3/wsgi.py, referer: http://127.0.0.1:89/
[Fri May 01 13:50:19.309379 2020] [authz_core:error] [pid 25] [client 172.17.0.1:49222] AH01630: client denied by server configuration: /Mxonline3/Mxonline3/wsgi.py
[Fri May 01 13:50:19.471692 2020] [authz_core:error] [pid 25] [client 172.17.0.1:49222] AH01630: client denied by server configuration: /Mxonline3/Mxonline3/wsgi.py, referer: http://127.0.0.1:89/
[Fri May 01 13:50:19.520806 2020] [authz_core:error] [pid 25] [client 172.17.0.1:49222] AH01630: client denied by server configuration: /Mxonline3/Mxonline3/wsgi.py
[Fri May 01 13:50:19.679379 2020] [authz_core:error] [pid 25] [client 172.17.0.1:49222] AH01630: client denied by server configuration: /Mxonline3/Mxonline3/wsgi.py, referer: http://127.0.0.1:89/
[Fri May 01 13:50:20.163507 2020] [authz_core:error] [pid 25] [client 172.17.0.1:49222] AH01630: client denied by server configuration: /Mxonline3/Mxonline3/wsgi.py
[Fri May 01 13:50:20.319872 2020] [authz_core:error] [pid 25] [client 172.17.0.1:49222] AH01630: client denied by server configuration: /Mxonline3/Mxonline3/wsgi.py, referer: http://127.0.0.1:89/
[Fri May 01 13:50:20.815076 2020] [authz_core:error] [pid 25] [client 172.17.0.1:49222] AH01630: client denied by server configuration: /Mxonline3/Mxonline3/wsgi.py
[Fri May 01 13:50:20.976441 2020] [authz_core:error] [pid 25] [client 172.17.0.1:49222] AH01630: client denied by server configuration: /Mxonline3/Mxonline3/wsgi.py, referer: http://127.0.0.1:89/
[Fri May 01 13:54:15.265685 2020] [wsgi:error] [pid 23] [client 172.17.0.1:49226] mod_wsgi (pid=23): Failed to exec Python script file '/Mxonline3/Mxonline3/wsgi.py'.
[Fri May 01 13:54:15.266161 2020] [wsgi:error] [pid 23] [client 172.17.0.1:49226] mod_wsgi (pid=23): Exception occurred processing WSGI script '/Mxonline3/Mxonline3/wsgi.py'.
[Fri May 01 13:54:15.270048 2020] [wsgi:error] [pid 23] [client 172.17.0.1:49226] Traceback (most recent call last):
[Fri May 01 13:54:15.270386 2020] [wsgi:error] [pid 23] [client 172.17.0.1:49226]   File "/Mxonline3/Mxonline3/wsgi.py", line 16, in <module>
[Fri May 01 13:54:15.270627 2020] [wsgi:error] [pid 23] [client 172.17.0.1:49226]     application = get_wsgi_application()
[Fri May 01 13:54:15.270854 2020] [wsgi:error] [pid 23] [client 172.17.0.1:49226]   File "/opt/app-root/lib/python3.6/site-packages/django/core/wsgi.py", line 12, in get_wsgi_application
[Fri May 01 13:54:15.271614 2020] [wsgi:error] [pid 23] [client 172.17.0.1:49226]     django.setup(set_prefix=False)
[Fri May 01 13:54:15.271854 2020] [wsgi:error] [pid 23] [client 172.17.0.1:49226]   File "/opt/app-root/lib/python3.6/site-packages/django/__init__.py", line 19, in setup
[Fri May 01 13:54:15.272079 2020] [wsgi:error] [pid 23] [client 172.17.0.1:49226]     configure_logging(settings.LOGGING_CONFIG, settings.LOGGING)
[Fri May 01 13:54:15.272339 2020] [wsgi:error] [pid 23] [client 172.17.0.1:49226]   File "/opt/app-root/lib/python3.6/site-packages/django/conf/__init__.py", line 76, in __getattr__
[Fri May 01 13:54:15.272529 2020] [wsgi:error] [pid 23] [client 172.17.0.1:49226]     self._setup(name)
[Fri May 01 13:54:15.272741 2020] [wsgi:error] [pid 23] [client 172.17.0.1:49226]   File "/opt/app-root/lib/python3.6/site-packages/django/conf/__init__.py", line 63, in _setup
[Fri May 01 13:54:15.272960 2020] [wsgi:error] [pid 23] [client 172.17.0.1:49226]     self._wrapped = Settings(settings_module)
[Fri May 01 13:54:15.273210 2020] [wsgi:error] [pid 23] [client 172.17.0.1:49226]   File "/opt/app-root/lib/python3.6/site-packages/django/conf/__init__.py", line 142, in __init__
[Fri May 01 13:54:15.273391 2020] [wsgi:error] [pid 23] [client 172.17.0.1:49226]     mod = importlib.import_module(self.SETTINGS_MODULE)
[Fri May 01 13:54:15.273633 2020] [wsgi:error] [pid 23] [client 172.17.0.1:49226]   File "/opt/app-root/lib64/python3.6/importlib/__init__.py", line 126, in import_module
[Fri May 01 13:54:15.273863 2020] [wsgi:error] [pid 23] [client 172.17.0.1:49226]     return _bootstrap._gcd_import(name[level:], package, level)
[Fri May 01 13:54:15.274136 2020] [wsgi:error] [pid 23] [client 172.17.0.1:49226]   File "<frozen importlib._bootstrap>", line 994, in _gcd_import
[Fri May 01 13:54:15.274332 2020] [wsgi:error] [pid 23] [client 172.17.0.1:49226]   File "<frozen importlib._bootstrap>", line 971, in _find_and_load
[Fri May 01 13:54:15.274532 2020] [wsgi:error] [pid 23] [client 172.17.0.1:49226]   File "<frozen importlib._bootstrap>", line 941, in _find_and_load_unlocked
[Fri May 01 13:54:15.274731 2020] [wsgi:error] [pid 23] [client 172.17.0.1:49226]   File "<frozen importlib._bootstrap>", line 219, in _call_with_frames_removed
[Fri May 01 13:54:15.274981 2020] [wsgi:error] [pid 23] [client 172.17.0.1:49226]   File "<frozen importlib._bootstrap>", line 994, in _gcd_import
[Fri May 01 13:54:15.275187 2020] [wsgi:error] [pid 23] [client 172.17.0.1:49226]   File "<frozen importlib._bootstrap>", line 971, in _find_and_load
[Fri May 01 13:54:15.275430 2020] [wsgi:error] [pid 23] [client 172.17.0.1:49226]   File "<frozen importlib._bootstrap>", line 953, in _find_and_load_unlocked
[Fri May 01 13:54:15.275695 2020] [wsgi:error] [pid 23] [client 172.17.0.1:49226] ModuleNotFoundError: No module named 'Mxonline3'
[Fri May 01 13:54:15.819477 2020] [wsgi:error] [pid 24] [client 172.17.0.1:49230] mod_wsgi (pid=24): Failed to exec Python script file '/Mxonline3/Mxonline3/wsgi.py'., referer: http://127.0.0.1:89/
[Fri May 01 13:54:15.820002 2020] [wsgi:error] [pid 24] [client 172.17.0.1:49230] mod_wsgi (pid=24): Exception occurred processing WSGI script '/Mxonline3/Mxonline3/wsgi.py'., referer: http://127.0.0.1:89/
[Fri May 01 13:54:15.824385 2020] [wsgi:error] [pid 24] [client 172.17.0.1:49230] Traceback (most recent call last):, referer: http://127.0.0.1:89/
[Fri May 01 13:54:15.824671 2020] [wsgi:error] [pid 24] [client 172.17.0.1:49230]   File "/Mxonline3/Mxonline3/wsgi.py", line 16, in <module>, referer: http://127.0.0.1:89/
[Fri May 01 13:54:15.824883 2020] [wsgi:error] [pid 24] [client 172.17.0.1:49230]     application = get_wsgi_application(), referer: http://127.0.0.1:89/
[Fri May 01 13:54:15.825166 2020] [wsgi:error] [pid 24] [client 172.17.0.1:49230]   File "/opt/app-root/lib/python3.6/site-packages/django/core/wsgi.py", line 12, in get_wsgi_application, referer: http://127.0.0.1:89/
[Fri May 01 13:54:15.825423 2020] [wsgi:error] [pid 24] [client 172.17.0.1:49230]     django.setup(set_prefix=False), referer: http://127.0.0.1:89/
[Fri May 01 13:54:15.825681 2020] [wsgi:error] [pid 24] [client 172.17.0.1:49230]   File "/opt/app-root/lib/python3.6/site-packages/django/__init__.py", line 19, in setup, referer: http://127.0.0.1:89/
[Fri May 01 13:54:15.825986 2020] [wsgi:error] [pid 24] [client 172.17.0.1:49230]     configure_logging(settings.LOGGING_CONFIG, settings.LOGGING), referer: http://127.0.0.1:89/
[Fri May 01 13:54:15.826258 2020] [wsgi:error] [pid 24] [client 172.17.0.1:49230]   File "/opt/app-root/lib/python3.6/site-packages/django/conf/__init__.py", line 76, in __getattr__, referer: http://127.0.0.1:89/
[Fri May 01 13:54:15.826546 2020] [wsgi:error] [pid 24] [client 172.17.0.1:49230]     self._setup(name), referer: http://127.0.0.1:89/
[Fri May 01 13:54:15.826811 2020] [wsgi:error] [pid 24] [client 172.17.0.1:49230]   File "/opt/app-root/lib/python3.6/site-packages/django/conf/__init__.py", line 63, in _setup, referer: http://127.0.0.1:89/
[Fri May 01 13:54:15.827067 2020] [wsgi:error] [pid 24] [client 172.17.0.1:49230]     self._wrapped = Settings(settings_module), referer: http://127.0.0.1:89/
[Fri May 01 13:54:15.827345 2020] [wsgi:error] [pid 24] [client 172.17.0.1:49230]   File "/opt/app-root/lib/python3.6/site-packages/django/conf/__init__.py", line 142, in __init__, referer: http://127.0.0.1:89/
[Fri May 01 13:54:15.827598 2020] [wsgi:error] [pid 24] [client 172.17.0.1:49230]     mod = importlib.import_module(self.SETTINGS_MODULE), referer: http://127.0.0.1:89/
[Fri May 01 13:54:15.827859 2020] [wsgi:error] [pid 24] [client 172.17.0.1:49230]   File "/opt/app-root/lib64/python3.6/importlib/__init__.py", line 126, in import_module, referer: http://127.0.0.1:89/
[Fri May 01 13:54:15.828096 2020] [wsgi:error] [pid 24] [client 172.17.0.1:49230]     return _bootstrap._gcd_import(name[level:], package, level), referer: http://127.0.0.1:89/
[Fri May 01 13:54:15.828354 2020] [wsgi:error] [pid 24] [client 172.17.0.1:49230]   File "<frozen importlib._bootstrap>", line 994, in _gcd_import, referer: http://127.0.0.1:89/
[Fri May 01 13:54:15.828597 2020] [wsgi:error] [pid 24] [client 172.17.0.1:49230]   File "<frozen importlib._bootstrap>", line 971, in _find_and_load, referer: http://127.0.0.1:89/
[Fri May 01 13:54:15.828837 2020] [wsgi:error] [pid 24] [client 172.17.0.1:49230]   File "<frozen importlib._bootstrap>", line 941, in _find_and_load_unlocked, referer: http://127.0.0.1:89/
[Fri May 01 13:54:15.829111 2020] [wsgi:error] [pid 24] [client 172.17.0.1:49230]   File "<frozen importlib._bootstrap>", line 219, in _call_with_frames_removed, referer: http://127.0.0.1:89/
[Fri May 01 13:54:15.829337 2020] [wsgi:error] [pid 24] [client 172.17.0.1:49230]   File "<frozen importlib._bootstrap>", line 994, in _gcd_import, referer: http://127.0.0.1:89/
[Fri May 01 13:54:15.829627 2020] [wsgi:error] [pid 24] [client 172.17.0.1:49230]   File "<frozen importlib._bootstrap>", line 971, in _find_and_load, referer: http://127.0.0.1:89/
[Fri May 01 13:54:15.829907 2020] [wsgi:error] [pid 24] [client 172.17.0.1:49230]   File "<frozen importlib._bootstrap>", line 953, in _find_and_load_unlocked, referer: http://127.0.0.1:89/
[Fri May 01 13:54:15.830197 2020] [wsgi:error] [pid 24] [client 172.17.0.1:49230] ModuleNotFoundError: No module named 'Mxonline3', referer: http://127.0.0.1:89/
[Fri May 01 13:54:53.977379 2020] [wsgi:error] [pid 25] [client 172.17.0.1:49234] mod_wsgi (pid=25): Failed to exec Python script file '/Mxonline3/Mxonline3/wsgi.py'.
[Fri May 01 13:54:53.977889 2020] [wsgi:error] [pid 25] [client 172.17.0.1:49234] mod_wsgi (pid=25): Exception occurred processing WSGI script '/Mxonline3/Mxonline3/wsgi.py'.
[Fri May 01 13:54:53.981564 2020] [wsgi:error] [pid 25] [client 172.17.0.1:49234] Traceback (most recent call last):
[Fri May 01 13:54:53.981805 2020] [wsgi:error] [pid 25] [client 172.17.0.1:49234]   File "/Mxonline3/Mxonline3/wsgi.py", line 16, in <module>
[Fri May 01 13:54:53.981990 2020] [wsgi:error] [pid 25] [client 172.17.0.1:49234]     application = get_wsgi_application()
[Fri May 01 13:54:53.982165 2020] [wsgi:error] [pid 25] [client 172.17.0.1:49234]   File "/opt/app-root/lib/python3.6/site-packages/django/core/wsgi.py", line 12, in get_wsgi_application
[Fri May 01 13:54:53.982339 2020] [wsgi:error] [pid 25] [client 172.17.0.1:49234]     django.setup(set_prefix=False)
[Fri May 01 13:54:53.982509 2020] [wsgi:error] [pid 25] [client 172.17.0.1:49234]   File "/opt/app-root/lib/python3.6/site-packages/django/__init__.py", line 19, in setup
[Fri May 01 13:54:53.982673 2020] [wsgi:error] [pid 25] [client 172.17.0.1:49234]     configure_logging(settings.LOGGING_CONFIG, settings.LOGGING)
[Fri May 01 13:54:53.982863 2020] [wsgi:error] [pid 25] [client 172.17.0.1:49234]   File "/opt/app-root/lib/python3.6/site-packages/django/conf/__init__.py", line 76, in __getattr__
[Fri May 01 13:54:53.983031 2020] [wsgi:error] [pid 25] [client 172.17.0.1:49234]     self._setup(name)
[Fri May 01 13:54:53.983201 2020] [wsgi:error] [pid 25] [client 172.17.0.1:49234]   File "/opt/app-root/lib/python3.6/site-packages/django/conf/__init__.py", line 63, in _setup
[Fri May 01 13:54:53.983356 2020] [wsgi:error] [pid 25] [client 172.17.0.1:49234]     self._wrapped = Settings(settings_module)
[Fri May 01 13:54:53.983536 2020] [wsgi:error] [pid 25] [client 172.17.0.1:49234]   File "/opt/app-root/lib/python3.6/site-packages/django/conf/__init__.py", line 142, in __init__
[Fri May 01 13:54:53.983709 2020] [wsgi:error] [pid 25] [client 172.17.0.1:49234]     mod = importlib.import_module(self.SETTINGS_MODULE)
[Fri May 01 13:54:53.983893 2020] [wsgi:error] [pid 25] [client 172.17.0.1:49234]   File "/opt/app-root/lib64/python3.6/importlib/__init__.py", line 126, in import_module
[Fri May 01 13:54:53.984052 2020] [wsgi:error] [pid 25] [client 172.17.0.1:49234]     return _bootstrap._gcd_import(name[level:], package, level)
[Fri May 01 13:54:53.984222 2020] [wsgi:error] [pid 25] [client 172.17.0.1:49234]   File "<frozen importlib._bootstrap>", line 994, in _gcd_import
[Fri May 01 13:54:53.984400 2020] [wsgi:error] [pid 25] [client 172.17.0.1:49234]   File "<frozen importlib._bootstrap>", line 971, in _find_and_load
[Fri May 01 13:54:53.984585 2020] [wsgi:error] [pid 25] [client 172.17.0.1:49234]   File "<frozen importlib._bootstrap>", line 941, in _find_and_load_unlocked
[Fri May 01 13:54:53.984783 2020] [wsgi:error] [pid 25] [client 172.17.0.1:49234]   File "<frozen importlib._bootstrap>", line 219, in _call_with_frames_removed
[Fri May 01 13:54:53.984957 2020] [wsgi:error] [pid 25] [client 172.17.0.1:49234]   File "<frozen importlib._bootstrap>", line 994, in _gcd_import
[Fri May 01 13:54:53.985118 2020] [wsgi:error] [pid 25] [client 172.17.0.1:49234]   File "<frozen importlib._bootstrap>", line 971, in _find_and_load
[Fri May 01 13:54:53.985289 2020] [wsgi:error] [pid 25] [client 172.17.0.1:49234]   File "<frozen importlib._bootstrap>", line 953, in _find_and_load_unlocked
[Fri May 01 13:54:53.985460 2020] [wsgi:error] [pid 25] [client 172.17.0.1:49234] ModuleNotFoundError: No module named 'Mxonline3'
[Fri May 01 13:54:54.442719 2020] [wsgi:error] [pid 22] [client 172.17.0.1:49238] mod_wsgi (pid=22): Failed to exec Python script file '/Mxonline3/Mxonline3/wsgi.py'., referer: http://127.0.0.1:89/
[Fri May 01 13:54:54.443118 2020] [wsgi:error] [pid 22] [client 172.17.0.1:49238] mod_wsgi (pid=22): Exception occurred processing WSGI script '/Mxonline3/Mxonline3/wsgi.py'., referer: http://127.0.0.1:89/
[Fri May 01 13:54:54.446444 2020] [wsgi:error] [pid 22] [client 172.17.0.1:49238] Traceback (most recent call last):, referer: http://127.0.0.1:89/
[Fri May 01 13:54:54.446698 2020] [wsgi:error] [pid 22] [client 172.17.0.1:49238]   File "/Mxonline3/Mxonline3/wsgi.py", line 16, in <module>, referer: http://127.0.0.1:89/
[Fri May 01 13:54:54.446911 2020] [wsgi:error] [pid 22] [client 172.17.0.1:49238]     application = get_wsgi_application(), referer: http://127.0.0.1:89/
[Fri May 01 13:54:54.447116 2020] [wsgi:error] [pid 22] [client 172.17.0.1:49238]   File "/opt/app-root/lib/python3.6/site-packages/django/core/wsgi.py", line 12, in get_wsgi_application, referer: http://127.0.0.1:89/
[Fri May 01 13:54:54.447304 2020] [wsgi:error] [pid 22] [client 172.17.0.1:49238]     django.setup(set_prefix=False), referer: http://127.0.0.1:89/
[Fri May 01 13:54:54.447532 2020] [wsgi:error] [pid 22] [client 172.17.0.1:49238]   File "/opt/app-root/lib/python3.6/site-packages/django/__init__.py", line 19, in setup, referer: http://127.0.0.1:89/
[Fri May 01 13:54:54.447762 2020] [wsgi:error] [pid 22] [client 172.17.0.1:49238]     configure_logging(settings.LOGGING_CONFIG, settings.LOGGING), referer: http://127.0.0.1:89/
[Fri May 01 13:54:54.447961 2020] [wsgi:error] [pid 22] [client 172.17.0.1:49238]   File "/opt/app-root/lib/python3.6/site-packages/django/conf/__init__.py", line 76, in __getattr__, referer: http://127.0.0.1:89/
[Fri May 01 13:54:54.448156 2020] [wsgi:error] [pid 22] [client 172.17.0.1:49238]     self._setup(name), referer: http://127.0.0.1:89/
[Fri May 01 13:54:54.448336 2020] [wsgi:error] [pid 22] [client 172.17.0.1:49238]   File "/opt/app-root/lib/python3.6/site-packages/django/conf/__init__.py", line 63, in _setup, referer: http://127.0.0.1:89/
[Fri May 01 13:54:54.448508 2020] [wsgi:error] [pid 22] [client 172.17.0.1:49238]     self._wrapped = Settings(settings_module), referer: http://127.0.0.1:89/
[Fri May 01 13:54:54.448711 2020] [wsgi:error] [pid 22] [client 172.17.0.1:49238]   File "/opt/app-root/lib/python3.6/site-packages/django/conf/__init__.py", line 142, in __init__, referer: http://127.0.0.1:89/
[Fri May 01 13:54:54.448891 2020] [wsgi:error] [pid 22] [client 172.17.0.1:49238]     mod = importlib.import_module(self.SETTINGS_MODULE), referer: http://127.0.0.1:89/
[Fri May 01 13:54:54.449041 2020] [wsgi:error] [pid 22] [client 172.17.0.1:49238]   File "/opt/app-root/lib64/python3.6/importlib/__init__.py", line 126, in import_module, referer: http://127.0.0.1:89/
[Fri May 01 13:54:54.449214 2020] [wsgi:error] [pid 22] [client 172.17.0.1:49238]     return _bootstrap._gcd_import(name[level:], package, level), referer: http://127.0.0.1:89/
[Fri May 01 13:54:54.449375 2020] [wsgi:error] [pid 22] [client 172.17.0.1:49238]   File "<frozen importlib._bootstrap>", line 994, in _gcd_import, referer: http://127.0.0.1:89/
[Fri May 01 13:54:54.449542 2020] [wsgi:error] [pid 22] [client 172.17.0.1:49238]   File "<frozen importlib._bootstrap>", line 971, in _find_and_load, referer: http://127.0.0.1:89/
[Fri May 01 13:54:54.449693 2020] [wsgi:error] [pid 22] [client 172.17.0.1:49238]   File "<frozen importlib._bootstrap>", line 941, in _find_and_load_unlocked, referer: http://127.0.0.1:89/
[Fri May 01 13:54:54.449891 2020] [wsgi:error] [pid 22] [client 172.17.0.1:49238]   File "<frozen importlib._bootstrap>", line 219, in _call_with_frames_removed, referer: http://127.0.0.1:89/
[Fri May 01 13:54:54.450084 2020] [wsgi:error] [pid 22] [client 172.17.0.1:49238]   File "<frozen importlib._bootstrap>", line 994, in _gcd_import, referer: http://127.0.0.1:89/
[Fri May 01 13:54:54.450251 2020] [wsgi:error] [pid 22] [client 172.17.0.1:49238]   File "<frozen importlib._bootstrap>", line 971, in _find_and_load, referer: http://127.0.0.1:89/
[Fri May 01 13:54:54.450425 2020] [wsgi:error] [pid 22] [client 172.17.0.1:49238]   File "<frozen importlib._bootstrap>", line 953, in _find_and_load_unlocked, referer: http://127.0.0.1:89/
[Fri May 01 13:54:54.450591 2020] [wsgi:error] [pid 22] [client 172.17.0.1:49238] ModuleNotFoundError: No module named 'Mxonline3', referer: http://127.0.0.1:89/
[Fri May 01 13:56:42.780426 2020] [wsgi:error] [pid 26] [client 172.17.0.1:49242] mod_wsgi (pid=26): Failed to exec Python script file '/Mxonline3/Mxonline3/wsgi.py'.
[Fri May 01 13:56:42.780968 2020] [wsgi:error] [pid 26] [client 172.17.0.1:49242] mod_wsgi (pid=26): Exception occurred processing WSGI script '/Mxonline3/Mxonline3/wsgi.py'.
[Fri May 01 13:56:42.785035 2020] [wsgi:error] [pid 26] [client 172.17.0.1:49242] Traceback (most recent call last):
[Fri May 01 13:56:42.785421 2020] [wsgi:error] [pid 26] [client 172.17.0.1:49242]   File "/Mxonline3/Mxonline3/wsgi.py", line 14, in <module>
[Fri May 01 13:56:42.785677 2020] [wsgi:error] [pid 26] [client 172.17.0.1:49242]     print(BASE_DIR)
[Fri May 01 13:56:42.785952 2020] [wsgi:error] [pid 26] [client 172.17.0.1:49242] NameError: name 'BASE_DIR' is not defined
[Fri May 01 13:56:43.014029 2020] [wsgi:error] [pid 23] [client 172.17.0.1:49246] mod_wsgi (pid=23): Failed to exec Python script file '/Mxonline3/Mxonline3/wsgi.py'., referer: http://127.0.0.1:89/
[Fri May 01 13:56:43.014932 2020] [wsgi:error] [pid 23] [client 172.17.0.1:49246] mod_wsgi (pid=23): Exception occurred processing WSGI script '/Mxonline3/Mxonline3/wsgi.py'., referer: http://127.0.0.1:89/
[Fri May 01 13:56:43.019719 2020] [wsgi:error] [pid 23] [client 172.17.0.1:49246] Traceback (most recent call last):, referer: http://127.0.0.1:89/
[Fri May 01 13:56:43.020163 2020] [wsgi:error] [pid 23] [client 172.17.0.1:49246]   File "/Mxonline3/Mxonline3/wsgi.py", line 14, in <module>, referer: http://127.0.0.1:89/
[Fri May 01 13:56:43.020489 2020] [wsgi:error] [pid 23] [client 172.17.0.1:49246]     print(BASE_DIR), referer: http://127.0.0.1:89/
[Fri May 01 13:56:43.020847 2020] [wsgi:error] [pid 23] [client 172.17.0.1:49246] NameError: name 'BASE_DIR' is not defined, referer: http://127.0.0.1:89/
[Fri May 01 13:56:43.953996 2020] [wsgi:error] [pid 46] [client 172.17.0.1:49250] mod_wsgi (pid=46): Failed to exec Python script file '/Mxonline3/Mxonline3/wsgi.py'.
[Fri May 01 13:56:43.954674 2020] [wsgi:error] [pid 46] [client 172.17.0.1:49250] mod_wsgi (pid=46): Exception occurred processing WSGI script '/Mxonline3/Mxonline3/wsgi.py'.
[Fri May 01 13:56:43.958839 2020] [wsgi:error] [pid 46] [client 172.17.0.1:49250] Traceback (most recent call last):
[Fri May 01 13:56:43.959199 2020] [wsgi:error] [pid 46] [client 172.17.0.1:49250]   File "/Mxonline3/Mxonline3/wsgi.py", line 14, in <module>
[Fri May 01 13:56:43.959490 2020] [wsgi:error] [pid 46] [client 172.17.0.1:49250]     print(BASE_DIR)
[Fri May 01 13:56:43.959771 2020] [wsgi:error] [pid 46] [client 172.17.0.1:49250] NameError: name 'BASE_DIR' is not defined
[Fri May 01 13:56:44.114760 2020] [wsgi:error] [pid 24] [client 172.17.0.1:49254] mod_wsgi (pid=24): Failed to exec Python script file '/Mxonline3/Mxonline3/wsgi.py'., referer: http://127.0.0.1:89/
[Fri May 01 13:56:44.115205 2020] [wsgi:error] [pid 24] [client 172.17.0.1:49254] mod_wsgi (pid=24): Exception occurred processing WSGI script '/Mxonline3/Mxonline3/wsgi.py'., referer: http://127.0.0.1:89/
[Fri May 01 13:56:44.119400 2020] [wsgi:error] [pid 24] [client 172.17.0.1:49254] Traceback (most recent call last):, referer: http://127.0.0.1:89/
[Fri May 01 13:56:44.119813 2020] [wsgi:error] [pid 24] [client 172.17.0.1:49254]   File "/Mxonline3/Mxonline3/wsgi.py", line 14, in <module>, referer: http://127.0.0.1:89/
[Fri May 01 13:56:44.120189 2020] [wsgi:error] [pid 24] [client 172.17.0.1:49254]     print(BASE_DIR), referer: http://127.0.0.1:89/
[Fri May 01 13:56:44.120461 2020] [wsgi:error] [pid 24] [client 172.17.0.1:49254] NameError: name 'BASE_DIR' is not defined, referer: http://127.0.0.1:89/
[Fri May 01 14:03:44.751051 2020] [wsgi:error] [pid 23] [client 172.17.0.1:49258] mod_wsgi (pid=23): Failed to exec Python script file '/Mxonline3/Mxonline3/wsgi.py'.
[Fri May 01 14:03:44.751616 2020] [wsgi:error] [pid 23] [client 172.17.0.1:49258] mod_wsgi (pid=23): Exception occurred processing WSGI script '/Mxonline3/Mxonline3/wsgi.py'.
[Fri May 01 14:03:44.755650 2020] [wsgi:error] [pid 23] [client 172.17.0.1:49258] Traceback (most recent call last):
[Fri May 01 14:03:44.755956 2020] [wsgi:error] [pid 23] [client 172.17.0.1:49258]   File "/Mxonline3/Mxonline3/wsgi.py", line 14, in <module>
[Fri May 01 14:03:44.756219 2020] [wsgi:error] [pid 23] [client 172.17.0.1:49258]     print(BASE_DIR)
[Fri May 01 14:03:44.756461 2020] [wsgi:error] [pid 23] [client 172.17.0.1:49258] NameError: name 'BASE_DIR' is not defined
[Fri May 01 14:03:45.252614 2020] [wsgi:error] [pid 24] [client 172.17.0.1:49262] mod_wsgi (pid=24): Failed to exec Python script file '/Mxonline3/Mxonline3/wsgi.py'., referer: http://127.0.0.1:89/
[Fri May 01 14:03:45.253097 2020] [wsgi:error] [pid 24] [client 172.17.0.1:49262] mod_wsgi (pid=24): Exception occurred processing WSGI script '/Mxonline3/Mxonline3/wsgi.py'., referer: http://127.0.0.1:89/
[Fri May 01 14:03:45.256664 2020] [wsgi:error] [pid 24] [client 172.17.0.1:49262] Traceback (most recent call last):, referer: http://127.0.0.1:89/
[Fri May 01 14:03:45.256908 2020] [wsgi:error] [pid 24] [client 172.17.0.1:49262]   File "/Mxonline3/Mxonline3/wsgi.py", line 14, in <module>, referer: http://127.0.0.1:89/
[Fri May 01 14:03:45.257128 2020] [wsgi:error] [pid 24] [client 172.17.0.1:49262]     print(BASE_DIR), referer: http://127.0.0.1:89/
[Fri May 01 14:03:45.257351 2020] [wsgi:error] [pid 24] [client 172.17.0.1:49262] NameError: name 'BASE_DIR' is not defined, referer: http://127.0.0.1:89/
[Fri May 01 14:03:45.952383 2020] [wsgi:error] [pid 27] [client 172.17.0.1:49266] mod_wsgi (pid=27): Failed to exec Python script file '/Mxonline3/Mxonline3/wsgi.py'.
[Fri May 01 14:03:45.952846 2020] [wsgi:error] [pid 27] [client 172.17.0.1:49266] mod_wsgi (pid=27): Exception occurred processing WSGI script '/Mxonline3/Mxonline3/wsgi.py'.
[Fri May 01 14:03:45.956822 2020] [wsgi:error] [pid 27] [client 172.17.0.1:49266] Traceback (most recent call last):
[Fri May 01 14:03:45.957160 2020] [wsgi:error] [pid 27] [client 172.17.0.1:49266]   File "/Mxonline3/Mxonline3/wsgi.py", line 14, in <module>
[Fri May 01 14:03:45.957381 2020] [wsgi:error] [pid 27] [client 172.17.0.1:49266]     print(BASE_DIR)
[Fri May 01 14:03:45.957616 2020] [wsgi:error] [pid 27] [client 172.17.0.1:49266] NameError: name 'BASE_DIR' is not defined
[Fri May 01 14:03:46.385685 2020] [wsgi:error] [pid 26] [client 172.17.0.1:49270] mod_wsgi (pid=26): Failed to exec Python script file '/Mxonline3/Mxonline3/wsgi.py'., referer: http://127.0.0.1:89/
[Fri May 01 14:03:46.386146 2020] [wsgi:error] [pid 26] [client 172.17.0.1:49270] mod_wsgi (pid=26): Exception occurred processing WSGI script '/Mxonline3/Mxonline3/wsgi.py'., referer: http://127.0.0.1:89/
[Fri May 01 14:03:46.389686 2020] [wsgi:error] [pid 26] [client 172.17.0.1:49270] Traceback (most recent call last):, referer: http://127.0.0.1:89/
[Fri May 01 14:03:46.389987 2020] [wsgi:error] [pid 26] [client 172.17.0.1:49270]   File "/Mxonline3/Mxonline3/wsgi.py", line 14, in <module>, referer: http://127.0.0.1:89/
[Fri May 01 14:03:46.390230 2020] [wsgi:error] [pid 26] [client 172.17.0.1:49270]     print(BASE_DIR), referer: http://127.0.0.1:89/
[Fri May 01 14:03:46.390561 2020] [wsgi:error] [pid 26] [client 172.17.0.1:49270] NameError: name 'BASE_DIR' is not defined, referer: http://127.0.0.1:89/
[Fri May 01 14:09:43.877921 2020] [wsgi:error] [pid 24] [client 172.17.0.1:49282] mod_wsgi (pid=24): Failed to exec Python script file '/Mxonline3/Mxonline3/wsgi.py'.
[Fri May 01 14:09:43.878406 2020] [wsgi:error] [pid 24] [client 172.17.0.1:49282] mod_wsgi (pid=24): Exception occurred processing WSGI script '/Mxonline3/Mxonline3/wsgi.py'.
[Fri May 01 14:09:43.882071 2020] [wsgi:error] [pid 24] [client 172.17.0.1:49282] Traceback (most recent call last):
[Fri May 01 14:09:43.882341 2020] [wsgi:error] [pid 24] [client 172.17.0.1:49282]   File "/Mxonline3/Mxonline3/wsgi.py", line 16, in <module>
[Fri May 01 14:09:43.882567 2020] [wsgi:error] [pid 24] [client 172.17.0.1:49282]     sys.path.insert(0, BASE_DIR)
[Fri May 01 14:09:43.882809 2020] [wsgi:error] [pid 24] [client 172.17.0.1:49282] NameError: name 'sys' is not defined
[Fri May 01 14:09:44.438811 2020] [wsgi:error] [pid 23] [client 172.17.0.1:49286] mod_wsgi (pid=23): Failed to exec Python script file '/Mxonline3/Mxonline3/wsgi.py'., referer: http://127.0.0.1:89/
[Fri May 01 14:09:44.439240 2020] [wsgi:error] [pid 23] [client 172.17.0.1:49286] mod_wsgi (pid=23): Exception occurred processing WSGI script '/Mxonline3/Mxonline3/wsgi.py'., referer: http://127.0.0.1:89/
[Fri May 01 14:09:44.442195 2020] [wsgi:error] [pid 23] [client 172.17.0.1:49286] Traceback (most recent call last):, referer: http://127.0.0.1:89/
[Fri May 01 14:09:44.442410 2020] [wsgi:error] [pid 23] [client 172.17.0.1:49286]   File "/Mxonline3/Mxonline3/wsgi.py", line 16, in <module>, referer: http://127.0.0.1:89/
[Fri May 01 14:09:44.442590 2020] [wsgi:error] [pid 23] [client 172.17.0.1:49286]     sys.path.insert(0, BASE_DIR), referer: http://127.0.0.1:89/
[Fri May 01 14:09:44.442811 2020] [wsgi:error] [pid 23] [client 172.17.0.1:49286] NameError: name 'sys' is not defined, referer: http://127.0.0.1:89/
